Traceback (most recent call last):
  File "/home/laser/miniconda3/envs/revamp/lib/python3.11/site-packages/jupyter_cache/executors/utils.py", line 58, in single_nb_execution
    executenb(
  File "/home/laser/miniconda3/envs/revamp/lib/python3.11/site-packages/nbclient/client.py", line 1305, in execute
    return NotebookClient(nb=nb, resources=resources, km=km, **kwargs).execute()
           ^^^^^^^^^^^^^^^^^^^^^^^^^^^^^^^^^^^^^^^^^^^^^^^^^^^^^^^^^^^^^^^^^^^^^
  File "/home/laser/miniconda3/envs/revamp/lib/python3.11/site-packages/jupyter_core/utils/__init__.py", line 168, in wrapped
    return loop.run_until_complete(inner)
           ^^^^^^^^^^^^^^^^^^^^^^^^^^^^^^
  File "/home/laser/miniconda3/envs/revamp/lib/python3.11/asyncio/base_events.py", line 653, in run_until_complete
    return future.result()
           ^^^^^^^^^^^^^^^
  File "/home/laser/miniconda3/envs/revamp/lib/python3.11/site-packages/nbclient/client.py", line 705, in async_execute
    await self.async_execute_cell(
  File "/home/laser/miniconda3/envs/revamp/lib/python3.11/site-packages/nbclient/client.py", line 1058, in async_execute_cell
    await self._check_raise_for_error(cell, cell_index, exec_reply)
  File "/home/laser/miniconda3/envs/revamp/lib/python3.11/site-packages/nbclient/client.py", line 914, in _check_raise_for_error
    raise CellExecutionError.from_cell_and_msg(cell, exec_reply_content)
nbclient.exceptions.CellExecutionError: An error occurred while executing the following cell:
------------------
key_regions = make_key_region_summary_table(df, "key_regions")
key_regions.head(10)
------------------


[0;31m---------------------------------------------------------------------------[0m
[0;31mTypeError[0m                                 Traceback (most recent call last)
Cell [0;32mIn[28], line 1[0m
[0;32m----> 1[0m key_regions [38;5;241m=[39m [43mmake_key_region_summary_table[49m[43m([49m[43mdf[49m[43m,[49m[43m [49m[38;5;124;43m"[39;49m[38;5;124;43mkey_regions[39;49m[38;5;124;43m"[39;49m[43m)[49m
[1;32m      2[0m key_regions[38;5;241m.[39mhead([38;5;241m10[39m)

File [0;32m~/git/coup/notebooks/utils.py:785[0m, in [0;36mmake_key_region_summary_table[0;34m(df, mutate_dataframe, *groupby_args, **groupby_kwargs)[0m
[1;32m    783[0m groupby_kwargs [38;5;241m=[39m [38;5;28mdict[39m(groupby_kwargs, group_keys[38;5;241m=[39m[38;5;28;01mFalse[39;00m)
[1;32m    784[0m [38;5;28;01mif[39;00m mutate_dataframe:
[0;32m--> 785[0m     df [38;5;241m=[39m [43madd_bass_degree_columns[49m[43m([49m
[1;32m    786[0m [43m        [49m[43mdf[49m[43m,[49m[43m [49m[43mmutate_dataframe[49m[38;5;241;43m=[39;49m[43mmutate_dataframe[49m[43m,[49m[43m [49m[38;5;241;43m*[39;49m[43mgroupby_args[49m[43m,[49m[43m [49m[38;5;241;43m*[39;49m[38;5;241;43m*[39;49m[43mgroupby_kwargs[49m
[1;32m    787[0m [43m    [49m[43m)[49m
[1;32m    788[0m [38;5;28;01melse[39;00m:
[1;32m    789[0m     add_bass_degree_columns(
[1;32m    790[0m         df, mutate_dataframe[38;5;241m=[39mmutate_dataframe, [38;5;241m*[39mgroupby_args, [38;5;241m*[39m[38;5;241m*[39mgroupby_kwargs
[1;32m    791[0m     )

[0;31mTypeError[0m: add_bass_degree_columns() got an unexpected keyword argument 'group_keys'

